Traceback (most recent call last):
  File "<pyshell#14>", line 2, in <module>
Exception: This is the eroor message.
